Workbook

Sheet Controle
A1: Data | B1: RAZÃO SOCIAL | C1: CNPJ | D1: Regime Tributário | E1: Status | F1: Região | I1: INSUMOS | J1: SUBVENÇÃO | K1: ICMS ST DA BC PIS E COF | L1: Exclusao Icms base pis e cof | M1: PIS E COFINS DA BASE - JUDC | N1: PREVIDENCIARIO | O1: REPORTO | V1: utilizado 11/2025
A2: 45954 | B2: FJC COMERCIO DE PRODUTO (Flavio) | C2: 22.802.549/0001-32 | D2: Lucro Presumido | E2: Fechado | F2: Brasilia - DF | I2: 0 | J2: 0 | K2: 0 | L2: 722125.02 | O2: 0
A3: 45964 | B3: POLISUPER DISTRIBUIDORA DE ALIMENTOS LTDA | C3: 07.369.040/0001-54 | D3: Lucro Real | E3: Relatório enviado. | F3: Rio de Janeiro - RJ | I3: 0 | J3: 0 | O3: 26942307
A4: 45965 | B4: MARAVISTA COMERCIO DE ALIMENTOS | C4: 30.140.610/0001-51 | D4: Lucro Real | E4: Fechado | F4: Niterói - RJ | I4: 2407515.1 | J4: 3376449.7 | O4: 0
A5: 45967 | B5: MARICA TAXI AEREO LTDA | C5: 31.548.241/0001-01 | D5: Lucro Real | E5: Relatório enviado. | F5: Rio de Janeiro - RJ | I5: 522124.32 | J5: 0 | O5: 0
A6: 45967 | B6: L.C.D. ENGENHARIA, CONSTRUCOES, MONTAGENS E MANUTENCOES | C6: 03.593.765/0001-70 | D6: Lucro Real | E6: Relatório enviado. | F6: Rio de Janeiro - RJ | I6: 0 | J6: 0 | O6: 0
A7: 45968 | B7: GRANO E FARINA PADARIA E COMERCIO LTDA | C7: 29.056.262/0001-50 | D7: Lucro Real | E7: Fechado | F7: Rio de Janeiro - RJ | I7: 642805.11 | J7: 0 | O7: 0 | Q7: 4 TRIM 2022 56896,31 | T7: =56896.31/3 -> 18965.437 | U7: =V7+18900 -> 18900
A8: 45968 | B8: J PINTO COMÉRCIO DE ALIMENTOS (SERRA AZUL) | C8: 11.820.069/0001-88 | D8: Lucro Real | E8: Relatório enviado. | F8: Friburgo - RJ | I8: 0 | J8: 0 | O8: 0
A9: 45975 | B9: CGX COMÉRCIO DE ALIMENTOS | D9: Lucro Real | E9: Fechado | F9: Rio de Janeiro - RJ | J9: 707943.48 | O9: 11437879 | P9: CONFIRMAR O QUE COMPENSOU SE FOI SUB
A10: 45978 | B10: SUPERMERCADO GUIMARAES FILHOS LTDA | C10: 50.547.492/0001-08 | D10: Lucro Real | E10: Fechado | F10: Saquarema - RJ | I10: =373277.7+560260 -> 933537.7 | J10: 0 | K10: 260360 | O10: 0 | V10: 117993.79
A11: 45978 | B11: USINA DE LEITE PARAISO LTDA | C11: 45.621.875/0001-49 | D11: Lucro Real | E11: Relatório enviado. | F11: São Gonçalo - RJ | I11: 778264.12 | J11: 0 | O11: 0
A12: 45987 | B12: IMPERIUM GENEROS ALIMENTICIOS LTDA | C12: 13.159.094/0001-98 | D12: Lucro Real | E12: Fechado | F12: Macaé - RJ | I12: R$ - | J12: 1548067.5 | O12: 7266275.3
A13: 45987 | B13: PEROLA DE NITEROI SUPERMERCADOS LTDA | C13: 16.564.133/0001-20 | D13: Lucro Real | E13: Fechado | F13: Niterói - RJ | I13: 2913132 | J13: 1047001.6 | O13: 10016407
A14: 46004 | B14: MERCEARIA 6 ESTRELAS LTDA (Paulo) | C14: 22.546.657/0001-91 | D14: Lucro Real | E14: Fechado | F14: Rio de Janeiro - RJ | I14: R$ - | J14: 664997.86 | O14: 0
A15: 46004 | B15: SUPERMERCADO COURTS LTDA | C15: 00.569.560/0001-61 | D15: Lucro Real | E15: Fechado | F15: Rio de Janeiro - RJ | I15: =560700 -> 560700 | J15: 307600.53 | O15: 0
A16: 46007 | B16: SUPREMO ( FALTA CONTRATO INSUMO E ST) | D16: Lucro Real | E16: Fechado | I16: =318000+280300 -> 598300 | J16: 0 | K16: 250600 | O16: 0
A17: 46007 | B17: SÃO FERNANDO | D17: Lucro Real | E17: Fechado | I17: 1484315.4 | J17: 0 | K17: =244589.91*32%+244589.91 -> 322858.68 | M17: 1484315.4 | O17: 25809822
A18: 46007 | B18: LGH | D18: Lucro Real | E18: Fechado | I18: 30100 | J18: 132566 | K18: 0 | O18: 0
A19: 46007 | B19: FEIRA NOVA | D19: Lucro Real | I19: R$ - | J19: 0 | K19: 0 | O19: 0
A20: 46008 | B20: MERCEARIA BAR TEMPO BOM | C20: 31.862.204.0001-65 | D20: Lucro Real | I20: 36904.1 | J20: 0 | K20: 86290.71 | M20: 654351.76 | O20: 0
A21: 46008 | B21: MERCEARIA E COMERCIO DE CEREAIS DO PARQUE UNIÃO | C21: 11.272.592/0001-17 | D21: Lucro Real | I21: R$ - | J21: 0 | K21: 0 | M21: 500742 | O21: 0
A22: 46008 | B22: LONGOS VALES | C22: 30.118.426/0001-05 | D22: Lucro Real | I22: 30094.94 | J22: 122123.54 | K22: 0 | M22: 202899.53 | O22: 0
A23: 46008 | B23: DONA BALBINA | C23: 32.028.466/0001-91 | D23: Lucro Real | I23: 23668.49 | J23: 549451.31 | K23: 158364.73 | O23: 0
A24: 46008 | B24: SUPERMERCADO LIBERDADE | C24: 09.633.032/0001-07 | D24: Lucro Real | E24: Fechado | I24: 150000 | J24: 647083.86 | K24: 0 | O24: 0
A25: 46008 | B25: MERCADO E PADARIA L M LOUZADA LTDA | C25: 13.537.908/0001-80 | D25: Lucro Real | I25: R$ - | J25: 60536.11 | K25: 0 | O25: 0
A26: 46008 | B26: AP MEDEIROS | C26: 31.224.769/0001-17 | D26: Lucro real | E26: fechado | I26: 1913869.3 | J26: 1609135.9 | K26: 0 | M26: 755091 | O26: 0
A27: 46035 | B27: SUPERMERCADOS FEIRA NOVA LTDA | C27: 36.525.319/0001-88 | D27: Lucro real | F27: RJ | K27: 1238461.5 | O27: 69435690
A28: 46035 | B28: SUPERMERCADO ECONOMICO JJ LTDA | C28: 22.536.813/0001-33 | D28: Lucro real | F28: RJ | J28: 1668605 | K28: 196871.06 | M28: 867813.12
A29: 46035 | B29: REZENDE ALIMENTOS NOVA HOLANDA LTDA | C29: 32.254.332/0001-99 | D29: Lucro real | F29: RJ | I29: 80560 | J29: 420212.41 | K29: 2283.29 | M29: 134852.29
A30: 46035 | B30: REZENDE ALIMENTOS JPA LTDA | C30: 50.250.937/0001-93 | D30: Lucro real | F30: RJ | I30: =65444.12+350150 -> 415594.12 | J30: =166415.66*47%+166415.66 -> 244631.02 | K30: 12131.07 | M30: 93215.06
A31: 46035 | B31: MERCADO 24 HORAS DA ROCINHA LTDA | C31: 23.672.895/0001-06 | D31: Lucro real | F31: RJ | I31: 250360 | J31: 956644.91 | K31: =22728.26+200260 -> 222988.26 | M31: 385910.66
A32: 46035 | B32: MULTI ALIMENTOS MENDANHA LTDA | D32: Lucro real | F32: RJ | I32: 100560 | J32: 312522.82 | K32: 4879.67 | M32: 155295.58 | O32: 0
A33: 46035 | B33: REZENDE ALIMENTOS CDD LTDA | C33: 28.782.157/0001-20 | D33: Lucro real | F33: RJ | I33: =59198.8+14795.54+3831.28+202634.68 -> 280460.3 | J33: 1146481 | K33: 173889.96 | M33: 527184.36 | O33: 0
A34: 46035 | B34: COMERCIAL 2 REZENDE ALIMENTOS LTDA | C34: 17.479.543/0001-36 | D34: Lucro real | F34: RJ | I34: =90560 -> 90560 | K34: =26911.21*42%+26911.21 -> 38213.918 | M34: 283514.39
A35: 46037 | B35: COMERCIAL DE ALIMENTOS PRIMUS | C35: 05.904.970/0001-35 | D35: Lucro real | F35: SP | I35: 1050143.7 | J35: 127712.31 | M35: 102282.67
A36: 46037 | B36: COMERCIAL DE ALIMENTOS MANO | C36: 05.904.978/0001-00 | D36: Lucro real | F36: SP | I36: 358617.91 | J36: 206005.26 | M36: 100616.03
A37: 46037 | B37: SHOPPING D CARNE BOI DE OURO | C37: 13.373.989/0001-20 | D37: Lucro real | F37: SP | I37: 677054.61 | J37: 61872.72 | M37: 54882.96
A38: 46048 | B38: SOUZA E CAMPOS COM DE PROD ALIMENTICIOS EIRELI | C38: 34.852.621/0001-15 | D38: Lucro real | F38: RJ | I38: 160500.3 | J38: 35260.3
A39: 46050 | B39: UNIÃO DA FAMILIA MERCEARIA LTDA | C39: 20.782.168/0001-03 | D39: Lucro Rela | F39: RJ | I39: =51265.4+80560.36+50210 -> 182035.76
A40: 46050 | B40: MERCADO UNIÃO DE NOVA BRASILIA LTDA | C40: 30.285.758/0001-84 | D40: Lucro Real | F40: RJ | I40: 110745.4
...

Sheet fluxo caixa dez 2025
A1: NOVEMBRO - 2025
A2: EMPRESAS | B2: CNPJ | C2: VALORES COMPENSADOS | H2: Honários | I2: % | J2: Comp. | M2: atualizar depois da compensação
C3: INSS | D3: PIS COFINS | E3: IRPJ CSLL | F3: DCTWEB 4/2025 | G3: TOTAL | M3: SALDO DE CRÉDITO INSUMOS | N3: SALDO DE CRÉDITO SUBV | O3: CREDITO EXLUSAO ICMS DA BC PIS E CF
A4: FJC COMERCIO DE PRODUTO (Flavio) | B4: 22.802.549/0001-32 | C4: =550+1617.91 -> 2167.91 | D4: =23274.52+107420.86 -> 130695.38 | E4: =40189.59+78319 -> 118508.59 | G4: =SUM(C4:E4) -> 251371.88 | H4: =G4*20% -> 50274.376 | I4: 0.2 | J4: NOVEMBRO | O4: =Controle!L2-'fluxo caixa dez 2025'!G4-400753.14-70000 -> 0
A5: MARAVISTA COMERCIO DE ALIMENTOS | B5: 30.140.610/0001-51 | C5: =121149.25+2796.47+145792.97 -> 269738.69 | D5: =55445.15+11938.37 -> 67383.52 | E5: 0 | G5: =SUM(C5:E5) -> 337122.21 | H5: =G5*20% -> 67424.442 | I5: 0.2 | J5: NOVEMBRO
A6: GRANO E FARINA PADARIA E COMERCIO LTDA | B6: 29.056.262/0001-50 | C6: =44429.04-10380.51-613.59+30726.88-7265.51 -> 56896.31 | D6: =6965.65+1512.28 -> 8477.93 | E6: =6322.64+13745.94 -> 20068.58 | G6: =SUM(C6:E6) -> 85442.82 | H6: =G6*12.5% -> 10680.353 | I6: 0.125 | J6: NOVEMBRO
A7: CGX COMÉRCIO DE ALIMENTOS | B7: 15.580.294/0001-45 | C7: =54353.17-12505.84-1756.26+32504.75 -> 72595.82 | D7: 0 | E7: =55517.35+11562.88 -> 67080.23 | G7: =SUM(C7:E7) -> 139676.05 | H7: =G7*12.5% -> 17459.506 | I7: 0.125 | J7: NOVEMBRO
A8: SUPERMERCADO GUIMARAES FILHOS LTDA | B8: 50.547.492/0001-08 | C8: =126798.45-26963.53-612.25+75619.09-16088.51 -> 158753.25 | D8: 18747.8 | E8: 0 | G8: =SUM(C8:E8) -> 177501.05 | H8: =G8*12.5% -> 22187.631 | I8: 0.125 | J8: NOVEMBRO
A9: PEROLA DE NITEROI SUPERMERCADOS LTDA | B9: 16.564.133/0001-20 | C9: =345.39+17627.13+66154.05+70374.83 -> 154501.4 | D9: =42687.23 -> 42687.23 | E9: 0 | G9: =SUM(C9:E9) -> 197188.63 | H9: =G9*15% -> 29578.295 | I9: 0.15 | J9: NOVEMBRO
A10: SUPERMERCADO COURTS LTDA | B10: 00.569.560/0001-61 | C10: =33555.84+9052.25+40957.53+10688.16+230.7 -> 94484.48 | D10: =3130.3+14508.58 -> 17638.88 | G10: =SUM(C10:E10) -> 112123.36 | H10: =G10*20% -> 22424.672 | I10: 0.2 | J10: NOVEMBRO
A11: MERCEARIA 6 ESTRELAS LTDA (Paulo) | B11: 22.546.657/0001-91 | C11: =23510.63+18052.74 -> 41563.37 | D11: 0 | E11: =14611.14+5980.08 -> 20591.22 | G11: =SUM(C11:E11) -> 62154.59 | H11: =G11*20% -> 12430.918 | I11: 0.2 | J11: NOVEMBRO
A12: IMPERIUM | B12: 13.159.094/0001-98 | C12: 0 | D12: 0 | E12: 0 | F12: 0 | G12: =SUM(C12:E12) -> 0 | H12: =G12*20% -> 0 | I12: 0.2 | J12: NOVEMBRO
A13: SUPERMERCADO LIBERDADE | B13: 09.633.032/0001-07 | C13: 0 | D13: =1781.76+8212.75 -> 9994.51 | G13: =SUM(C13:E13) -> 9994.51 | H13: =G13*20% -> 1998.902 | I13: 0.2 | J13: NOVEMBRO
A14: SÃO FERNANDO 10 | B14: 11.304.945/0001-13 | C14: 0 | E14: =57891.61+21560.98 -> 79452.59 | G14: =C14+D14+E14 -> 79452.59 | H14: =G14*15% -> 11917.888 | I14: 0.15 | J14: NOVEMBRO
A15: SUPREMO | B15: 05.229.674/0001-86 | C15: =27417.66+33265.63 -> 60683.29 | D15: 0 | E15: 0 | G15: =SUM(C15:E15) -> 60683.29 | H15: =G15*20% -> 12136.658 | I15: 0.2 | J15: NOVEMBRO
A16: LGH | B16: 26.061.062/0001-05 | C16: =948.27+3131.81 -> 4080.08 | G16: =SUM(C16:E16) -> 4080.08 | H16: =G16*20% -> 816.016 | I16: 0.2 | J16: NOVEMBRO | M16: =Controle!I18-G16 -> 26019.92 | N16: =Controle!J18-'fluxo caixa dez 2025'!G16 -> 128485.92
A17: AP MEDEIROS | B17: 31.224.769/0001-17 | C17: =114051.55-10926.48-43.62+32149.2-7128.61 -> 128102.04 | D17: =53396.12+11592.58 -> 64988.7 | E17: =56654.8+21115.73 -> 77770.53 | F17: =98020.51+36239.52+35320.31+903.22+2324.22+15.9+191.04+4415.02+353.18+1765.99+269+1059.59+31.83 -> 180909.33 | G17: =SUM(C17:E17)+F17 -> 451770.6 | H17: =G17*20% -> 90354.12 | I17: 0.2 | J17: NOVEMBRO | M17: =Controle!I26-C17-D17-E17 -> 1643008 | N17: =Controle!J26 -> 1609135.9
A18: SUPERMERCADOS FEIRA NOVA LTDA | B18: 36.525.319/0001-88 | C18: 0 | D18: 0 | E18: 0 | F18: 0 | G18: =SUM(C18:E18)+F18 -> 0 | H18: =SUM(D18:F18)+G18 -> 0 | J18: NOVEMBRO
A19: SUPERMERCADO ECONOMICO JJ LTDA | B19: 22.536.813/0001-33 | C19: 0 | D19: 0 | E19: 0 | F19: 0 | G19: =SUM(C19:E19)+F19 -> 0 | H19: =SUM(D19:F19)+G19 -> 0 | J19: NOVEMBRO
A20: REZENDE ALIMENTOS NOVA HOLANDA LTDA | B20: 32.254.332/0001-99 | C20: 0 | D20: 0 | E20: 0 | F20: 0 | G20: =SUM(C20:E20)+F20 -> 0 | H20: =SUM(D20:F20)+G20 -> 0 | J20: NOVEMBRO
A21: REZENDE ALIMENTOS JPA LTDA | B21: 50.250.937/0001-93 | C21: 0 | D21: 0 | E21: 0 | F21: 0 | G21: =SUM(C21:E21)+F21 -> 0 | H21: =SUM(D21:F21)+G21 -> 0 | J21: NOVEMBRO
A22: MERCADO 24 HORAS DA ROCINHA LTDA | B22: 23.672.895/0001-06 | C22: 0 | D22: 0 | E22: 0 | F22: 0 | G22: =SUM(C22:E22)+F22 -> 0 | H22: =SUM(D22:F22)+G22 -> 0 | J22: NOVEMBRO
A23: MULTI ALIMENTOS MENDANHA LTDA | B23: 30.807.561/0001-68 | C23: 0 | D23: 0 | E23: 0 | F23: 0 | G23: =SUM(C23:E23)+F23 -> 0 | H23: =SUM(D23:F23)+G23 -> 0 | J23: NOVEMBRO
A24: REZENDE ALIMENTOS CDD LTDA | B24: 28.732.157/0001-20 | C24: 0 | D24: 0 | E24: 0 | F24: 0 | G24: =SUM(C24:E24)+F24 -> 0 | H24: =SUM(D24:F24)+G24 -> 0 | J24: NOVEMBRO
A25: COMERCIAL 2 REZENDE ALIMENTOS LTDA | B25: 17.479.543/0001-36 | C25: 0 | D25: 0 | E25: 0 | F25: 0 | G25: =SUM(C25:E25)+F25 -> 0 | H25: =SUM(D25:F25)+G25 -> 0 | J25: NOVEMBRO
A26: COMERCIAL DE ALIMENTOS PRIMUS | B26: 05.904.970/0001-35 | C26: 0 | D26: 0 | E26: 0 | F26: 0 | G26: =SUM(C26:E26)+F26 -> 0 | H26: =SUM(D26:F26)+G26 -> 0 | J26: NOVEMBRO
A27: COMERCIAL DE ALIMENTOS MANO | B27: 05.904.978/0001-00 | C27: 0 | D27: 0 | E27: 0 | F27: 0 | G27: =SUM(C27:E27)+F27 -> 0 | H27: =SUM(D27:F27)+G27 -> 0 | J27: NOVEMBRO
A28: SHOPPING D CARNE BOI DE OURO | B28: 13.373.989/0001-20 | C28: 0 | D28: 0 | E28: 0 | F28: 0 | G28: =SUM(C28:E28)+F28 -> 0 | H28: =SUM(D28:F28)+G28 -> 0 | J28: NOVEMBRO
A29: UNIÃO DA FAMILIA MERCEARIA LTDA | B29: 20.782.168/0001-03 | C29: 0 | D29: 0 | E29: 0 | F29: 0 | G29: =SUM(C29:E29)+F29 -> 0 | H29: =SUM(D29:F29)+G29 -> 0 | J29: NOVEMBRO
... A40: MERCADINHO PAI E FILHA | B40: 18.108.211/0001-08 | C40: 0 | D40: 0 | E40: 0 | F40: 0 | G40: =SUM(C40:E40)+F40 -> 0 | H40: =SUM(D40:F40)+G40 -> 0 | J40: NOVEMBRO
A41: TOTAL | C41: =SUM(C4:C40) -> 1043566.6 | D41: =SUM(D4:D40) -> 360613.95 | E41: =SUM(E4:E40) -> 383471.74 | F41: =SUM(F4:F40) -> 180909.33 | G41: =SUM(G4:G40) -> 1968561.7 | H41: =SUM(H4:H40) -> 349683.78

Sheet Fluxo de caixa
A1: EMPRESAS | B1: CNPJ | C1: VALORES COMPENSADOS
C2: DCTF WEB | D2: PIS COFINS | E2: IRPJ CSLL | F2: TOTAL | H2: SALDO DE CRÉDITO | J2: Honários | K2: Vencimento
A3: FJC COMERCIO DE PRODUTO (Flavio) | B3: 22.802.549/0001-32 | C3: 0 | D3: =24602.48+113549.52 -> 138152 | E3: =76745.72+42522.69 -> 119268.41 | F3: =SUM(C3:E3) -> 257420.41 | H3: =#N/A -> #N/A | J3: =F3*20% -> 51484.082 | K3: 45966
A5: 45992
A6: EMPRESAS | B6: CNPJ | C6: VALORES COMPENSADOS
C7: DCTF WEB | D7: PIS COFINS | E7: IRPJ CSLL | F7: TOTAL | H7: SALDO DE CRÉDITO | J7: Honários | K7: Vencimento
A8: FJC COMERCIO DE PRODUTO (Flavio) | B8: 22.802.549/0001-32 | C8: 2514.14 | D8: =104619.49+22667.55 -> 127287.04 | E8: 119268.41 | F8: =E8+D8+C8 -> 249069.59 | H8: =H3-F8 -> #N/A | J8: =F8*20% -> 49813.918 | K8: 45996
A9: MARAVISTA COMERCIO DE ALIMENTOS | B9: 30.140.610/0001-51 | C9: 146996.58 | D9: 94554.96 | E9: 0 | F9: =E9+D9+C9 -> 241551.54 | H9: =#N/A -> #N/A | J9: =F9*15% -> 36232.731 | K9: 45996
A10: GRANO E FARINA PADARIA E COMERCIO LTDA | B10: 29.056.262/0001-50 | C10: 43115.11 | D10: =6599.93+1432.88 -> 8032.81 | E10: 0 | F10: =E10+D10+C10 -> 51147.92 | H10: =#N/A -> #N/A | J10: =F10*20% -> 10229.584 | K10: 45996
A11: CGX COMÉRCIO DE ALIMENTOS | B11: 15.580.294/0001-45 | C11: 55341.01 | D11: 0 | E11: 0 | F11: =E11+D11+C11 -> 55341.01 | H11: =#N/A -> #N/A | J11: =F11*20% -> 11068.202 | K11: 45996
A12: SUPERMERCADO GUIMARAES FILHOS LTDA | B12: 50.547.492/0001-08 | C12: 113840.57 | D12: =4998.63+23955.46 -> 28954.09 | E12: 0 | F12: =E12+D12+C12 -> 142794.66 | H12: =#N/A -> #N/A | J12: =F12*12.5% -> 17849.333 | K12: 45988
A13: PEROLA
A14: 6 ESTRELAS
A15: CURTIS
A16: MANCEBO (VERIFICAR SE TEM GUIA A PAGAR)
A17: MANCEBO (VERIFICAR SE TEM GUIA A PAGAR)

Sheet fluxo caixa jan 2026
A1: DEZEMBRO - 2025
A2: EMPRESAS | B2: CNPJ | C2: VALORES COMPENSADOS | H2: Honários | I2: % | J2: Comp. | K2: VL NFSE- ENVIO | N2: atualizar depois da compensação
C3: INSS | D3: PIS COFINS | E3: IRPJ CSLL | F3: DCTWEb IRPJ/CS 3 TRIM /PIS-COF | G3: TOTAL | L3: ENVIO BOLETO | N3: SALDO DE CRÉDITO INSUMOS | O3: SALDO DE CRÉDITO SUBV | P3: CREDITO EXLUSAO ICMS DA BC PIS E CF | Q3: SALDO | R3: DCOMPS | S3: DCOMPS | T3: DCOMPS | U3: DCOMPS | V3: DCOMPS | W3: DCOMPS | X3: DCOMPS | Y3: DCOMPS | Z3: DCOMPS | AA3: DCOMPS | AB3: DCOMPS | AC3: DCOMPS | AD3: DCOMPS | AE3: DCOMPS | AF3: DCOMPS | AG3: DCOMPS
A4: MARAVISTA COMERCIO DE ALIMENTOS | B4: 30.140.610/0001-51 | C4: =935.94+130292.96 -> 131228.9 | D4: =120437.45+20032.11 -> 140469.56 | E4: 0 | G4: =SUM(C4:E4) -> 271698.46 | H4: =G4*15% -> 40754.769 | I4: 0.15 | J4: DEZEMBRO | K4: =H4-16856.11 -> 23898.659 | M4: ir mensal | N4: =Controle!I4-'fluxo caixa dez 2025'!G5-'fluxo caixa jan 2026'!G4 -> 1798694.4 | O4: ='fluxo caixa dez 2025'!N5 -> 0 | R4: 17300.78779.160126.1.3.19-2064 | S4: 33883.13403.160126.1.3.19-2817 | V4: 23621.25335.230126.1.3.19-5490 | Y4: 03761.93908.230126.1.3.19-5961
A5: GRANO E FARINA PADARIA E COMERCIO LTDA | B5: 29.056.262/0001-50 | C5: =14.61+28597.08 -> 28611.69 | D5: =7172.46+1557.18 -> 8729.64 | E5: =31995.17+13678.26 -> 45673.43 | F5: =6965.65+1512.28 -> 8477.93 | G5: =SUM(C5:F5) -> 91492.69 | H5: =G5*12.5% -> 11436.586 | I5: 0.125 | J5: DEZEMBRO | K5: =H5-175.49 -> 11261.096 | N5: =Controle!I7-'fluxo caixa dez 2025'!G6-'fluxo caixa jan 2026'!G5 -> 465869.6 | O5: ='fluxo caixa dez 2025'!N6 -> 0 | R5: 04095.95327.150126.1.3.19-3931 | S5: 25341.13808.150126.1.3.19-1044 | V5: 07357.28543.230126.1.3.19-9597 | Y5: 39634.47398.280126.1.1.19-4068 | AB5: 07053.49133.280126.1.3.19-0027
A6: CGX COMÉRCIO DE ALIMENTOS | B6: 15.580.294/0001-45 | C6: =126.43+7490.92+29915.73 -> 37533.08 | D6: 0 | E6: =117113.29+44320.78 -> 161434.07 | G6: =SUM(C6:E6) -> 198967.15 | H6: =G6*12.5% -> 24870.894 | I6: 0.125 | J6: DEZEMBRO | K6: =H6-1195.94 -> 23674.954 | N6: 0 | O6: ='fluxo caixa dez 2025'!N7-G6 -> -198967.15 | R6: 25341.13808.150126.1.3.19-1044 | S6: 04095.95327.150126.1.3.19-3931
A7: SUPERMERCADO GUIMARAES FILHOS LTDA | B7: 50.547.492/0001-08 | C7: =77493.14+19258.98+113.33+28.3 -> 96893.75 | D7: =7767.74+36041.33 -> 43809.07 | E7: 0 | G7: =SUM(C7:E7) -> 140702.82 | H7: =G7*12.5% -> 17587.853 | I7: 0.125 | J7: DEZEMBRO | K7: =H7 -> 17587.853 | N7: =Controle!I10-'fluxo caixa dez 2025'!G8-'fluxo caixa jan 2026'!G7 -> 615333.83 | O7: 0 | R7: 14818.19074.160126.1.3.19-6800 | S7: 21279.35657.160126.1.3.19-3315
A8: PEROLA DE NITEROI SUPERMERCADOS LTDA | B8: 16.564.133/0001-20 | C8: =78998.75+304.38 -> 79303.13 | D8: =46532.24+10102.4 -> 56634.64 | E8: =133600.09+50256.03 -> 183856.12 | G8: =SUM(C8:E8) -> 319793.89 | H8: =G8*15% -> 47969.084 | I8: 0.15 | J8: DEZEMBRO | K8: =H8 -> 47969.084 | N8: =Controle!I13-'fluxo caixa dez 2025'!G9-'fluxo caixa jan 2026'!G8 -> 2396149.5 | O8: =Controle!J13 -> 1047001.6 | R8: 15030.94485.150126.1.3.19-0562 | S8: 34384.31549.150126.1.3.19-7678 | V8: 08268.04410.230126.1.3.19-6086 | Y8: 16899.18729.280126.1.3.19-6950
A9: SUPERMERCADO COURTS LTDA | B9: 00.569.560/0001-61 | C9: =49803.2+262.02 -> 50065.22 | D9: =13521.85+2923.39 -> 16445.24 | E9: =9420.05+5551.22 -> 14971.27 | G9: =SUM(C9:E9) -> 81481.73 | H9: =G9*20% -> 16296.346 | I9: 0.2 | J9: DEZEMBRO | K9: =H9 -> 16296.346 | O9: ='fluxo caixa dez 2025'!N10-G9 -> -81481.73 | R9: 02405.91673.150126.1.3.19-6918 | S9: 09003.01357.150126.1.3.19-7771 | V9: 08436.38790.270126.1.3.19-4052
A10: MERCEARIA 6 ESTRELAS LTDA (Paulo) | B10: 22.546.657/0001-91 | C10: =156.57+852.85+9390.58+5449.96+8945.84 -> 24795.8 | D10: 0 | E10: =157230.09+58762.83 -> 215992.92 | G10: =SUM(C10:E10) -> 240788.72 | H10: =G10*20% -> 48157.744 | I10: 0.2 | J10: DEZEMBRO | K10: =H10-4118.25 -> 44039.494 | O10: ='fluxo caixa dez 2025'!N11-G10 -> -240788.72 | R10: 01876.37126.150126.1.3.04-8750 | S10: 10244.34586.150126.1.3.04-3105 | V10: 15730.77247.150126.1.3.04-0557 | Y10: 16022.07223.150126.1.3.04-1039 | AB10: 24335.78821.150126.1.3.04-0608 | AE10: 07667.63853.270126.1.1.19-8302 | AH10: 41921.29564.270126.1.3.19-1902
A11: IMPERIUM | B11: 13.159.094/0001-98 | G11: =SUM(C11:E11) -> 0 | H11: =G11*20% -> 0 | I11: 0 | J11: DEZEMBRO | K11: =H11 -> 0 | N11: ='fluxo caixa dez 2025'!M12-G11 -> 0 | O11: ='fluxo caixa dez 2025'!N12-G11 -> 0
A12: SUPERMERCADO LIBERDADE | B12: 09.633.032/0001-07 | C12: =78.19+19197.87+2439.97 -> 21716.03 | D12: =11220.42+2420.38 -> 13640.8 | E12: =20125.8+9405.29 -> 29531.09 | G12: =SUM(C12:E12) -> 64887.92 | H12: =G12*15% -> 9733.188 | I12: 0.15 | J12: DEZEMBRO | K12: =H12 -> 9733.188 | N12: ='fluxo caixa dez 2025'!M13-G12 -> -64887.92 | O12: ='fluxo caixa dez 2025'!N13 -> 0 | R12: 22029.18618.150126.1.3.18-1435 | S12: 22232.78400.150126.1.3.18-4459 | V12: 28773.61048.150126.1.3.19-3750 | AB12: 01314.10762.270126.1.3.18-3714
A13: SÃO FERNANDO 10 | B13: 11.304.945/0001-13 | C13: =98562.18+219.33 -> 98781.51 | D13: =57431.51+12295.37 -> 69726.88 | E13: =197425.47+73233.17 -> 270658.64 | G13: =C13+D13+E13 -> 439167.03 | H13: =G13*15% -> 65875.054 | I13: 0.15 | J13: DEZEMBRO | K13: =H13+2815.4 -> 68690.454 | N13: 0 | O13: 0 | P13: =Controle!K17-E13-12932.11 -> 39267.931 | R13: 18602.60343.150126.1.3.19-1062 | S13: 15744.48190.150126.1.3.19-0080 | V13: 41636.47156.261225.1.1.19-7607 | Y13: 25818.82650.261225.1.3.19-4104 | AB13: 19620.51548.270126.1.1.19-2231 | AE13: 27812.30712.270126.1.3.19-9856
A14: SUPREMO | B14: 05.229.674/0001-86 | C14: =142.36+12909.35+20446.58 -> 33498.29 | D14: =23086.57+5012.17 -> 28098.74 | E14: =67555.94+26480.14 -> 94036.08 | G14: =SUM(C14:E14) -> 155633.11 | H14: =G14*20% -> 31126.622 | I14: 0.2 | J14: DEZEMBRO | K14: =H14 -> 31126.622 | N14: ='fluxo caixa dez 2025'!M15-G14 -> -155633.11 | O14: 0 | R14: 33264.72763.150126.1.3.19-0989 | S14: 40157.33676.150126.1.3.19-2029 | V14: 40271.34269.150126.1.3.19-5938 | Y14: 37486.56052.230126.1.3.19-2957 | AB14: 17173.01128.280126.1.1.19-2013 | AE14: 11433.17846.280126.1.3.19-8040
A15: LGH | B15: 26.061.062/0001-05 | C15: 2762.4 | E15: =62937.17+24817.38 -> 87754.55 | G15: =SUM(C15:E15) -> 90516.95 | H15: =G15*20% -> 18103.39 | I15: 0.2 | J15: DEZEMBRO | K15: =H15 -> 18103.39 | N15: 0 | O15: ='fluxo caixa dez 2025'!N16-G15+26019.92 -> 63988.89 | R15: 26241.05281.160126.1.3.19-8900 | S15: 08495.28809.280126.1.3.19-2941 | V15: 12318.77957.280126.1.1.19-1580
A16: AP MEDEIROS | B16: 31.224.769/0001-17 | C16: =31376.89+2720.16 -> 34097.05 | D16: =50774.67+11023.45 -> 61798.12 | E16: =186463.07+69286.7 -> 255749.77 | G16: =C16+D16+E16 -> 351644.94 | H16: =G16*20% -> 70328.988 | I16: 0.2 | J16: DEZEMBRO | K16: =H16 -> 70328.988 | O16: ='fluxo caixa dez 2025'!N17-G16+33872.15 -> 1291363.1 | R16: 38218.51641.150126.1.3.18-2136 | S16: 26519.48994.150126.1.1.18-1809 | V16: 15942.32381.150126.1.3.18-9788 | Y16: 12267.25756.280126.1.1.19-1950 | AB16: 36923.64823.280126.1.3.19-9078
A17: SUPERMERCADOS FEIRA NOVA LTDA | B17: 36.525.319/0001-88 | C17: =716191.64+167391.14+2377.65+10949.55+492+106.61+164 -> 897672.59 | D17: 0 | G17: =C17+D17+E17 -> 897672.59 | H17: =G17*10% -> 89767.259 | I17: 0.1 | J17: DEZEMBRO | K17: =H17 -> 89767.259 | N17: 0 | O17: 0 | P17: =Controle!K27-'fluxo caixa jan 2026'!G17 -> 340788.89 | R17: 15058.02495.160126.1.3.19-4752
A18: SUPERMERCADO ECONOMICO JJ LTDA | B18: 22.536.813/0001-33 | C18: =100455.18+26388.95+13.27+258.23 -> 127115.63 | D18: =112707.04+24198.56 -> 136905.6 | E18: =90050.68+34578.25 -> 124628.93 | G18: =C18+D18+E18 -> 388650.16 | H18: =G18*15% -> 58297.524 | I18: 0.15 | J18: DEZEMBRO | K18: =H18 -> 58297.524 | O18: =Controle!J33 -> 1146481 | P18: 0 | R18: 25342.70439.230126.1.3.04-3340 | S18: 14009.83451.230126.1.3.04-7126 | V18: 35496.64570.230126.1.3.04-0380 | Y18: 03526.30462.230126.1.3.19-1778 | AB18: 08515.54513.240126.1.3.18-5868 | AE18: 01665.96498.270126.1.1.19-5080 | AH18: 34762.02234.270126.1.3.19-0029
A19: REZENDE ALIMENTOS NOVA HOLANDA LTDA | B19: 32.254.332/0001-99 | C19: 0 | D19: 0 | E19: =17017.27+8286.22 -> 25303.49 | G19: =C19+D19+E19+F19 -> 25303.49 | H19: =G19*12.5% -> 3162.9362 | I19: 0.125 | J19: DEZEMBRO | K19: =H19 -> 3162.9362 | N19: 0 | O19: =Controle!J29-G19+2283.29 -> 397192.21 | P19: =Controle!K29 -> 2283.29 | R19: 37478.68134.270126.1.1.19-0597 | S19: 18610.51180.290126.1.3.19-2723
A20: REZENDE ALIMENTOS JPA LTDA | B20: 50.250.937/0001-93 | C20: 0 | D20: 0 | E20: =171542.24+63915.21 -> 235457.45 | F20: =13964.06+13964.06+5747.06+5747.06+2674.68+6498.87 -> 48595.79 | G20: =C20+D20+E20+F20 -> 284053.24 | H20: =G20*12.5% -> 35506.655 | I20: 0.125 | J20: DEZEMBRO | K20: =H20 -> 35506.655 | N20: =Controle!I30 -> 415594.12 | O20: =Controle!J30-G20+65444.12+12131.07 -> 38152.97 | R20: 22899.53035.270126.1.1.19-0323 | S20: 31873.69683.270126.1.3.19-8961 | V20: 06161.76072.270126.1.1.18-9308
A21: MERCADO 24 HORAS DA ROCINHA LTDA | B21: 23.672.895/0001-06 | C21: 0 | D21: 0 | E21: =74334.87+28920.55 -> 103255.42 | F21: =7894.9+16999.48 -> 24894.38 | G21: =C21+D21+E21+F21 -> 128149.8 | H21: =G21*12.5% -> 16018.725 | I21: 0.125 | J21: DEZEMBRO | K21: =H21 -> 16018.725 | N21: 0 | O21: =Controle!J31 -> 956644.91 | P21: =Controle!K31-'fluxo caixa jan 2026'!G21 -> 94838.46 | R21: 30097.48283.160126.1.3.19-3338 | S21: 00019.48046.270126.1.3.19-0646
A22: MULTI ALIMENTOS MENDANHA LTDA | B22: 30.807.561/0001-68 | C22: 0 | D22: 0 | E22: =33633.61+14268.1 -> 47901.71 | F22: =3599.96+3599.96+2159.97+2159.97+1005.25+1675.42 -> 14200.53 | G22: =C22+D22+E22+F22 -> 62102.24 | H22: =G22*12.5% -> 7762.78 | I22: 0.125 | J22: DEZEMBRO | K22: =H22 -> 7762.78 | N22: 0 | O22: =Controle!J32-G22+4879.67 -> 255300.25 | P22: 0 | R22: 04132.22811.270126.1.1.19-0703 | S22: 07585.20794.270126.1.3.19-2363 | V22: 10598.28328.270126.1.3.19-6070
A23: REZENDE ALIMENTOS CDD LTDA | B23: 28.732.157/0001-20 | C23: 0 | D23: 0 | E23: =130100.69+48996.25 -> 179096.94 | F23: =8736.67+8736.67+3865.2+3865.2+1798.86+4066.05 -> 31068.65 | G23: =C23+D23+E23+F23 -> 210165.59 | H23: =G23*12.5% -> 26270.699 | I23: 0.125 | J23: DEZEMBRO | K23: =H23 -> 26270.699 | N23: =Controle!I33-'fluxo caixa jan 2026'!G23 -> 70294.71 | O23: =Controle!J33 -> 1146481 | P23: =Controle!K33+'fluxo caixa jan 2026'!N23 -> 244184.67 | R23: 13632.17123.270126.1.3.19-1696 | S23: 05937.54906.270126.1.1.19-7594 | V23: 15999.16611.270126.1.3.19-8479
A24: COMERCIAL 2 REZENDE ALIMENTOS LTDA | B24: 17.479.543/0001-36 | D24: 0 | E24: =32652.16+13914.78 -> 46566.94 | F24: =2036.94+2036.94+1222.16+1222.16+568.79+948 -> 8034.99 | G24: =C24+D24+E24+F24 -> 54601.93 | H24: =G24*12.5% -> 6825.2413 | I24: 0.125 | J24: DEZEMBRO | K24: =H24 -> 6825.2413 | N24: =Controle!I34-G24 -> 35958.07 | O24: 0 | P24: =Controle!K34 -> 38213.918 | R24: 21944.39559.270126.1.1.19-7641 | S24: 38713.19911.270126.1.3.19-8890 | V24: 37425.08119.270126.1.3.19-9802
A25: COMERCIAL DE ALIMENTOS PRIMUS | B25: 05.904.970/0001-35 | C25: =12616.09 -> 12616.09 | D25: 0 | E25: 0 | F25: 0 | G25: =C25+D25+E25 -> 12616.09 | H25: =G25*20% -> 2523.218 | I25: 0.2 | J25: DEZEMBRO | K25: =H25 -> 2523.218 | N25: =Controle!I35-'fluxo caixa jan 2026'!G25 -> 1037527.6 | O25: =Controle!J35 -> 127712.31 | R25: 33199.62621.160126.1.3.19-6938
A26: COMERCIAL DE ALIMENTOS MANO | B26: 05.904.978/0001-00 | C26: 944.88 | D26: 0 | F26: 0 | G26: =C26+D26+E26 -> 944.88 | H26: =G26*20% -> 188.976 | I26: 0.2 | J26: DEZEMBRO | K26: =H26 -> 188.976 | N26: =Controle!I36-'fluxo caixa jan 2026'!G26 -> 357673.03 | O26: =Controle!J36 -> 206005.26 | R26: 40088.79112.160126.1.3.19-3906
A27: SHOPPING D CARNE BOI DE OURO | B27: 13.373.989/0001-20 | C27: =4471.52+1055.9 -> 5527.42 | D27: 0 | E27: 0 | F27: 0 | G27: =C27+D27+E27 -> 5527.42 | H27: =G27*20% -> 1105.484 | I27: 0.2 | J27: DEZEMBRO | K27: =H27 -> 1105.484 | N27: =Controle!I37-'fluxo caixa jan 2026'!G27 -> 671527.19 | O27: =Controle!J37 -> 61872.72 | R27: 33465.68752.160126.1.3.19-6231
A28: UNIÃO DA FAMILIA MERCEARIA LTDA | B28: 20.782.168/0001-03 | C28: 0 | D28: 0 | E28: =12003.43+6481.23 -> 18484.66 | F28: 0 | G28: =C28+D28+E28+F28 -> 18484.66 | H28: =G28*20% -> 3696.932 | I28: 0.2 | J28: DEZEMBRO | K28: =H28 -> 3696.932 | N28: =Controle!I39-'fluxo caixa jan 2026'!G28 -> 163551.1 | R28: 24591.17799.290126.1.3.19-6281
A29: MERCADO UNIÃO DE NOVA BRASILIA LTDA | B29: 30.285.758/0001-84 | C29: 0 | D29: 0 | E29: =6049.24+3629.54 -> 9678.78 | F29: 0 | G29: =C29+D29+E29+F29 -> 9678.78 | H29: =G29*20% -> 1935.756 | I29: 0.2 | J29: DEZEMBRO | K29: =H29 -> 1935.756 | N29: =Controle!I40-'fluxo caixa jan 2026'!G29 -> 101066.62 | R29: 07278.67239.290126.1.1.19-9085 | S29: 36050.46345.290126.1.3.19-0817
A30: MULTIMIX | B30: 03.307.464/0001-33 | C30: 0 | D30: 0 | E30: 0 | F30: 0 | G30: =C30+D30+E30+F30 -> 0 | H30: =G30*20% -> 0 | I30: 0 | J30: DEZEMBRO | N30: =SUM(N4:N27) -> 7644101 | O30: =SUM(O4:O27) -> 6216958.7 | P30: =SUM(P4:P27) -> 759577.16 | Q30: =N30+O30+P30 -> 14620637
A31: EMPORIO PETROPOLIS | B31: 15.202.462/0001-69 | C31: 0 | D31: 0 | E31: 0 | F31: 0 | G31: =C31+D31+E31+F31 -> 0 | H31: =G31*20% -> 0 | I31: 0 | J31: DEZEMBRO
A32: PADARIA JANDRES | B32: 10.440.200/0001-19 | C32: 0 | D32: 0 | E32: 0 | F32: 0 | G32: =C32+D32+E32+F32 -> 0 | H32: =G32*20% -> 0 | I32: 0 | J32: DEZEMBRO | N32: =N30+O30+P30 -> 14620637
A33: REUNIDOS | B33: 32.352.751/0001-63 | C33: 0 | D33: 0 | E33: 0 | F33: 0 | G33: =C33+D33+E33+F33 -> 0 | H33: =G33*20% -> 0 | I33: 0 | J33: DEZEMBRO
A34: PRINCESA | B34: 27.833.615/0001-55 | C34: 0 | D34: 0 | E34: 0 | F34: 0 | G34: =C34+D34+E34+F34 -> 0 | H34: =G34*20% -> 0 | I34: 0 | J34: DEZEMBRO
A35: SOLIDCON BARRA INFORMATICA LTDA | B35: 04.782.837/0001-90 | C35: 0 | D35: 0 | E35: 0 | F35: 0 | G35: =C35+D35+E35+F35 -> 0 | H35: =G35*20% -> 0 | I35: 0 | J35: DEZEMBRO | M35: 590
A36: SUPERMERCADO CAMPOS NOVOS | B36: 33.333.713/0001-26 | C36: 0 | D36: 0 | E36: 0 | F36: 0 | G36: =C36+D36+E36+F36 -> 0 | H36: =G36*20% -> 0 | I36: 0 | J36: DEZEMBRO | M36: 560
A37: A M MACAE COMERCIO DE ALIMENTOS LTDA | B37: 18.343.960/0001-10 | C37: 0 | D37: 0 | E37: 0 | F37: 0 | G37: =C37+D37+E37+F37 -> 0 | H37: =G37*20% -> 0 | I37: 0 | J37: DEZEMBRO | M37: 2011
A38: SUPERMERCADO BATISTA | B38: 15.471.879/0001-27 | C38: 0 | D38: 0 | E38: 0 | F38: 0 | G38: =C38+D38+E38+F38 -> 0 | H38: =G38*20% -> 0 | I38: 0 | J38: DEZEMBRO | M38: 98
A39: MERCADINHO PAI E FILHA | B39: 18.108.211/0001-08 | C39: 0 | D39: 0 | E39: 0 | F39: 0 | G39: =C39+D39+E39+F39 -> 0 | H39: =G39*20% -> 0 | I39: 0 | J39: DEZEMBRO
A40: TOTAL | C40: =SUM(C4:C39) -> 1683163.5 | D40: =SUM(D4:D39) -> 576258.29 | E40: =SUM(E4:E39) -> 2150032.3 | F40: =SUM(F4:F39) -> 135272.27 | G40: =SUM(G4:G39) -> 4544726.3 | H40: =SUM(H4:H39) -> 655302.7 | J40: DEZEMBRO | R40: =11343.59+431.16+4537.43 -> 16312.18
...

Sheet fluxo caixa fev 2026
A1: JANEIRO - 2026
A2: EMPRESAS | B2: CNPJ | C2: VALORES COMPENSADOS | H2: Honários | I2: % | J2: Comp. | N2: atualizar depois da compensação
C3: INSS | D3: PIS COFINS | E3: IRPJ CSLL | F3: DCTWEb IRPJ/CS 3 TRIM /PIS-COF | G3: TOTAL | K3: VL NFSE- ENVIO | L3: ENVIO BOLETO | N3: SALDO DE CRÉDITO INSUMOS | O3: SALDO DE CRÉDITO SUBV | P3: CREDITO EXLUSAO ICMS DA BC PIS E CF | Q3: SALDO honorario projeção
A4: MARAVISTA COMERCIO DE ALIMENTOS | B4: 30.140.610/0001-51 | C4: =781.97+220.99+30602.44+116123.92 -> 147729.32 | D4: =63388.58+13734.19 -> 77122.77 | E4: 0 | F4: 0 | G4: =SUM(C4:E4) -> 224852.09 | H4: =G4*15% -> 33727.814 | I4: 0.15 | J4: JANEIRO | K4: =H4 -> 33727.814 | M4: ir mensal | N4: ='fluxo caixa jan 2026'!N4-'fluxo caixa fev 2026'!G4 -> 1573842.3 | O4: ='fluxo caixa dez 2025'!N5 -> 0 | Q4: =N4+O4*I4 -> 1573842.3 | R4: 1.0018664e+22 | S4: 1.0018664e+22
A5: GRANO E FARINA PADARIA E COMERCIO LTDA | B5: 29.056.262/0001-50 | C5: =23050.96+6224.91 -> 29275.87 | D5: =5922.4+1245.63 -> 7168.03 | E5: 0 | F5: 0 | G5: =SUM(C5:F5) -> 36443.9 | H5: =G5*12.5% -> 4555.4875 | I5: 0.125 | J5: JANEIRO | K5: =H5 -> 4555.4875 | N5: ='fluxo caixa jan 2026'!N5-'fluxo caixa fev 2026'!G5 -> 429425.7 | O5: ='fluxo caixa dez 2025'!N6 -> 0 | Q5: =N5+O5*I5 -> 429425.7
A6: CGX COMÉRCIO DE ALIMENTOS | B6: 15.580.294/0001-45 | C6: =8098.01+31015.58+128.31 -> 39241.9 | E6: 0 | F6: 0 | G6: =SUM(C6:E6) -> 39241.9 | H6: =G6*12.5% -> 4905.2375 | I6: 0.125 | J6: JANEIRO | K6: =H6 -> 4905.2375 | N6: 0 | O6: ='fluxo caixa jan 2026'!O6-'fluxo caixa fev 2026'!G6 -> -238209.05 | Q6: =N6+O6*I6 -> -29776.131
A7: SUPERMERCADO GUIMARAES FILHOS LTDA | B7: 50.547.492/0001-08 | C7: =113.98+216.64+2780.5+590.89+16762.64+78004.72 -> 98469.37 | D7: =14535.58+3069.05 -> 17604.63 | E7: 0 | F7: 0 | G7: =SUM(C7:E7) -> 116074 | H7: =G7*12.5% -> 14509.25 | I7: 0.125 | J7: JANEIRO | K7: =H7 -> 14509.25 | N7: ='fluxo caixa jan 2026'!N7-'fluxo caixa fev 2026'!G7 -> 499259.83 | O7: 0 | Q7: =N7+O7*I7 -> 499259.83
A8: PEROLA DE NITEROI SUPERMERCADOS LTDA | B8: 16.564.133/0001-20 | C8: =86794.6+9+331.55 -> 87135.15 | D8: =37668.1+8176.13 -> 45844.23 | E8: 0 | F8: 0 | G8: =SUM(C8:E8) -> 132979.38 | H8: =G8*15%-1475.88 -> 18471.027 | I8: 0.15 | J8: JANEIRO | K8: =H8 -> 18471.027 | N8: ='fluxo caixa jan 2026'!N8-'fluxo caixa fev 2026'!G8 -> 2263170.1 | O8: =Controle!J13 -> 1047001.6 | Q8: =N8+O8*I8 -> 2420220.3
A9: SUPERMERCADO COURTS LTDA | B9: 00.569.560/0001-61 | C9: =380.36+64.8+617.46+42805.87 -> 43868.49 | D9: =18468.32+3999.72 -> 22468.04 | E9: 0 | F9: 0 | G9: =SUM(C9:E9) -> 66336.53 | H9: =G9*20% -> 13267.306 | I9: 0.2 | J9: JANEIRO | K9: =H9 -> 13267.306 | O9: ='fluxo caixa jan 2026'!O9-'fluxo caixa fev 2026'!G9 -> -147818.26 | Q9: =N9+O9*I9 -> -29563.652
A10: MERCEARIA 6 ESTRELAS LTDA (Paulo) | B10: 22.546.657/0001-91 | C10: =5038.86+19215.32+156.57 -> 24410.75 | E10: 0 | F10: 0 | G10: =SUM(C10:E10) -> 24410.75 | H10: =G10*20% -> 4882.15 | I10: 0.2 | J10: JANEIRO | K10: =H10 -> 4882.15 | O10: ='fluxo caixa jan 2026'!O10-'fluxo caixa fev 2026'!G10 -> -265199.47 | Q10: =N10+O10*I10 -> -53039.894
A11: IMPERIUM | B11: 13.159.094/0001-98 | E11: 0 | F11: 0 | G11: =SUM(C11:E11) -> 0 | H11: =G11*20% -> 0 | I11: 0 | J11: JANEIRO | K11: =H11 -> 0 | N11: ='fluxo caixa dez 2025'!M12-G11 -> 0 | O11: ='fluxo caixa dez 2025'!N12-G11 -> 0 | Q11: =N11+O11*I11 -> 0
A12: SUPERMERCADO LIBERDADE | B12: 09.633.032/0001-07 | C12: =78.19+4766.82+19101.16 -> 23946.17 | D12: =1400.96+288.52 -> 1689.48 | E12: 0 | F12: 0 | G12: =SUM(C12:E12) -> 25635.65 | H12: =G12*15% -> 3845.3475 | I12: 0.15 | J12: JANEIRO | K12: =H12 -> 3845.3475 | N12: ='fluxo caixa jan 2026'!N12-'fluxo caixa fev 2026'!G12 -> -90523.57 | O12: ='fluxo caixa dez 2025'!N13 -> 0 | Q12: =N12+O12*I12 -> -90523.57
A13: SÃO FERNANDO 10 | B13: 11.304.945/0001-13 | C13: =219.33+6457.84+19914.56+73471.53 -> 100063.26 | D13: =18204.74+3859.76 -> 22064.5 | E13: 0 | F13: 0 | G13: =C13+D13+E13 -> 122127.76 | H13: =G13*15% -> 18319.164 | I13: 0.15 | J13: JANEIRO | K13: =H13 -> 18319.164 | N13: 0 | O13: 0 | P13: =Controle!K17-E13-12932.11 -> 309926.57 | Q13: =N13+O13*I13 -> 0
A14: SUPREMO | B14: 05.229.674/0001-86 | C14: =11.73+146.26+22594.83+6657.22+5111.05 -> 34521.09 | D14: =9342.51+2028.32 -> 11370.83 | E14: 0 | F14: 0 | G14: =SUM(C14:E14) -> 45891.92 | H14: =G14*20% -> 9178.384 | I14: 0.2 | J14: JANEIRO | K14: =H14 -> 9178.384 | N14: ='fluxo caixa jan 2026'!N14-'fluxo caixa fev 2026'!G14 -> -201525.03 | O14: 0 | Q14: =N14+O14*I14 -> -201525.03
A15: LGH | B15: 26.061.062/0001-05 | C15: =1990.14+80.69 -> 2070.83 | E15: 0 | F15: 0 | G15: =SUM(C15:E15) -> 2070.83 | H15: =G15*20% -> 414.166 | I15: 0.2 | J15: JANEIRO | K15: =H15 -> 414.166 | N15: 0 | O15: ='fluxo caixa jan 2026'!O15-'fluxo caixa fev 2026'!G15 -> 61918.06 | Q15: =N15+O15*I15 -> 12383.612
A16: AP MEDEIROS | B16: 31.224.769/0001-17 | C16: =6977.17+28223.86 -> 35201.03 | D16: =48144.99+10451.96 -> 58596.95 | E16: 0 | F16: 0 | G16: =C16+D16+E16 -> 93797.98 | H16: =G16*20% -> 18759.596 | I16: 0.2 | J16: JANEIRO | K16: =H16 -> 18759.596 | O16: ='fluxo caixa jan 2026'!O16-'fluxo caixa fev 2026'!G16 -> 1197565.1 | Q16: =N16+O16*I16 -> 239513.02
A17: SUPERMERCADOS FEIRA NOVA LTDA | B17: 36.525.319/0001-88 | C17: 340788.89 | D17: 0 | E17: 0 | F17: 0 | G17: =C17+D17+E17 -> 340788.89 | H17: =G17*10% -> 34078.889 | I17: 0.1 | J17: JANEIRO | K17: =H17 -> 34078.889 | N17: 0 | O17: 0 | P17: ='fluxo caixa jan 2026'!P17-'fluxo caixa fev 2026'!G17 -> 0 | Q17: =N17+O17*I17 -> 0
A18: SUPERMERCADO ECONOMICO JJ LTDA | B18: 22.536.813/0001-33 | C18: =26134.6+96286.66 -> 122421.26 | D18: =65510.84+14142.09 -> 79652.93 | E18: 0 | F18: 0 | G18: =C18+D18+E18 -> 202074.19 | H18: =G18*15% -> 30311.128 | I18: 0.15 | J18: JANEIRO | K18: =H18 -> 30311.128 | O18: ='fluxo caixa jan 2026'!O18-'fluxo caixa fev 2026'!G18 -> 944406.84 | P18: 0 | Q18: =N18+O18*I18 -> 141661.03
A19: REZENDE ALIMENTOS NOVA HOLANDA LTDA | B19: 32.254.332/0001-99 | C19: =156.86+1674.29+17.45+5.1 -> 1853.7 | D19: =6969.2+2103.34 -> 9072.54 | E19: 0 | F19: 0 | G19: =C19+D19+E19+F19 -> 10926.24 | H19: =G19*12.5% -> 1365.78 | I19: 0.125 | J19: JANEIRO | K19: =H19 -> 1365.78 | N19: 0 | O19: ='fluxo caixa jan 2026'!O19-'fluxo caixa fev 2026'!G19 -> 386265.97 | P19: =Controle!K29 -> 2283.29 | Q19: =N19+O19*I19 -> 48283.246
A20: REZENDE ALIMENTOS JPA LTDA | B20: 50.250.937/0001-93 | C20: =243.13+15.07+189.95 -> 448.15 | E20: 0 | F20: 0 | G20: =C20+D20+E20+F20 -> 448.15 | H20: =G20*12.5% -> 56.01875 | I20: 0.125 | J20: JANEIRO | K20: =H20 -> 56.01875 | N20: ='fluxo caixa jan 2026'!N20-'fluxo caixa fev 2026'!G20 -> 415145.97 | O20: =Controle!J30-G20+65444.12+12131.07 -> 321758.06 | Q20: =N20+O20*I20 -> 455365.73
A21: MERCADO 24 HORAS DA ROCINHA LTDA | B21: 23.672.895/0001-06 | C21: =185.37+24.22+47.26 -> 256.85 | D21: =22907.21+4950.97 -> 27858.18 | E21: 0 | F21: 0 | G21: =C21+D21+E21+F21 -> 28115.03 | H21: =G21*12.5% -> 3514.3787 | I21: 0.125 | J21: JANEIRO | K21: =H21 -> 3514.3787 | N21: 0 | O21: ='fluxo caixa jan 2026'!O18 -> 1146481 | P21: ='fluxo caixa jan 2026'!P21-'fluxo caixa fev 2026'!G21 -> 66723.43 | Q21: =N21+O21*I21 -> 143310.13
A22: MULTI ALIMENTOS MENDANHA LTDA | B22: 30.807.561/0001-68 | C22: =169.88+20.25+52.44 -> 242.57 | E22: 0 | F22: 0 | G22: =C22+D22+E22+F22 -> 242.57 | H22: =G22*12.5% -> 30.32125 | I22: 0.125 | J22: JANEIRO | K22: =H22 -> 30.32125 | N22: 0 | O22: ='fluxo caixa jan 2026'!O22-'fluxo caixa fev 2026'!G22 -> 255057.68 | P22: 0 | Q22: =N22+O22*I22 -> 31882.21
A23: REZENDE ALIMENTOS CDD LTDA | B23: 28.732.157/0001-20 | C23: =196.69+29.65+936.93+110.87 -> 1274.14 | D23: =10176.22+3275.58 -> 13451.8 | E23: 0 | F23: 0 | G23: =C23+D23+E23+F23 -> 14725.94 | H23: =G23*12.5% -> 1840.7425 | I23: 0.125 | J23: JANEIRO | K23: =H23 -> 1840.7425 | N23: 0 | O23: ='fluxo caixa jan 2026'!O23-'fluxo caixa fev 2026'!G23 -> 1131755.1 | P23: ='fluxo caixa jan 2026'!P23-'fluxo caixa fev 2026'!G23 -> 229458.73 | Q23: =N23+O23*I23 -> 141469.39
A24: COMERCIAL 2 REZENDE ALIMENTOS LTDA | B24: 17.479.543/0001-36 | C24: =104.13+1674.66+993.08 -> 2771.87 | E24: 0 | F24: 0 | G24: =C24+D24+E24+F24 -> 2771.87 | H24: =G24*12.5% -> 346.48375 | I24: 0.125 | J24: JANEIRO | K24: =H24 -> 346.48375 | N24: ='fluxo caixa jan 2026'!N24-'fluxo caixa fev 2026'!G24 -> 33186.2 | O24: 0 | P24: =Controle!K34 -> 38213.918 | Q24: =N24+O24*I24 -> 33186.2
A25: COMERCIAL DE ALIMENTOS PRIMUS | B25: 05.904.970/0001-35 | C25: =12760.99 -> 12760.99 | D25: 0 | E25: 0 | F25: 0 | G25: =C25+D25+E25 -> 12760.99 | H25: =G25*20% -> 2552.198 | I25: 0.2 | J25: JANEIRO | K25: =H25 -> 2552.198 | N25: ='fluxo caixa jan 2026'!N25-'fluxo caixa fev 2026'!G25 -> 1024766.6 | O25: =Controle!J35 -> 127712.31 | Q25: =N25+O25*I25 -> 1050309.1
A26: COMERCIAL DE ALIMENTOS MANO | B26: 05.904.978/0001-00 | C26: =704.68 -> 704.68 | D26: 0 | E26: 0 | F26: 0 | G26: =C26+D26+E26 -> 704.68 | H26: =G26*20% -> 140.936 | I26: 0.2 | J26: JANEIRO | K26: =H26 -> 140.936 | N26: ='fluxo caixa jan 2026'!N26-'fluxo caixa fev 2026'!G26 -> 356968.35 | O26: =Controle!J36 -> 206005.26 | Q26: =N26+O26*I26 -> 398169.4
A27: SHOPPING D CARNE BOI DE OURO | B27: 13.373.989/0001-20 | C27: =5938.74 -> 5938.74 | D27: 0 | E27: 0 | F27: 0 | G27: =C27+D27+E27 -> 5938.74 | H27: =G27*20% -> 1187.748 | I27: 0.2 | J27: JANEIRO | K27: =H27 -> 1187.748 | N27: ='fluxo caixa jan 2026'!N27-'fluxo caixa fev 2026'!G27 -> 665588.45 | O27: =Controle!J37 -> 61872.72 | Q27: =N27+O27*I27 -> 677962.99
A28: UNIÃO DA FAMILIA MERCEARIA LTDA | B28: 20.782.168/0001-03 | C28: =8441.59+63.43 -> 8505.02 | D28: =352.74+1689.22 -> 2041.96 | E28: 0 | F28: 0 | G28: =C28+D28+E28+F28 -> 10546.98 | H28: =G28*20% -> 2109.396 | I28: 0.2 | J28: JANEIRO | K28: =H28 -> 2109.396 | N28: ='fluxo caixa jan 2026'!N28-'fluxo caixa fev 2026'!G28 -> 153004.12 | Q28: =N28+O28*I28 -> 153004.12
A29: MERCADO UNIÃO DE NOVA BRASILIA LTDA | B29: 30.285.758/0001-84 | C29: =1328.83+5346.19+63.43 -> 6738.45 | D29: =962.76+209.02 -> 1171.78 | E29: 0 | F29: 0 | G29: =C29+D29+E29+F29 -> 7910.23 | H29: =G29*20% -> 1582.046 | I29: 0.2 | J29: JANEIRO | K29: =H29 -> 1582.046 | N29: ='fluxo caixa jan 2026'!N29-'fluxo caixa fev 2026'!G29 -> 93156.39 | Q29: =N29+O29*I29 -> 93156.39 | R29: 4.1937811e+20 | S29: 2.4894114e+22 | T29: 4.1524508e+22
A30: MULTIMIX | B30: 03.307.464/0001-33 | C30: 0 | E30: 0 | F30: 0 | G30: =C30+D30+E30+F30 -> 0 | H30: =G30*20% -> 0 | I30: 0 | J30: JANEIRO | K30: =H30 -> 0 | Q30: =N30+O30*I30 -> 0
A31: EMPORIO PETROPOLIS | B31: 15.202.462/0001-69 | C31: 0 | E31: 0 | F31: 0 | G31: =C31+D31+E31+F31 -> 0 | H31: =G31*20% -> 0 | I31: 0 | J31: JANEIRO | K31: =H31 -> 0 | Q31: =N31+O31*I31 -> 0
A32: PADARIA JANDRES | B32: 10.440.200/0001-19 | C32: 0 | D32: =15533.03+3372.24 -> 18905.27 | E32: 0 | F32: 0 | G32: =C32+D32+E32+F32 -> 18905.27 | H32: =G32*20% -> 3781.054 | I32: 0 | J32: JANEIRO | N32: =Controle!I43-'fluxo caixa fev 2026'!G32 -> 181345.33 | Q32: =N32+O32*I32 -> 181345.33
A33: REUNIDOS | B33: 32.352.751/0001-63 | C33: 0 | D33: 0 | E33: 0 | F33: 0 | G33: 0 | H33: 0 | I33: 0 | J33: JANEIRO | K33: =SUM(K4:K29) -> 223951 | N33: =SUM(N4:N27) -> 6969304.9 | O33: =SUM(O4:O27) -> 6236573 | P33: =SUM(P4:P27) -> 646605.94 | Q33: =SUM(Q4:Q32) -> 8319321.8
A34: PRINCESA | B34: 27.833.615/0001-55 | C34: 0 | D34: 0 | E34: 0 | F34: 0 | G34: 0 | H34: 0 | I34: 0 | J34: JANEIRO | K34: =K33*20% -> 44790.199
A35: SOLIDCON BARRA INFORMATICA LTDA | B35: 04.782.837/0001-90 | C35: 0 | D35: 0 | E35: 0 | F35: 0 | G35: 0 | H35: 0 | I35: 0 | J35: JANEIRO | K35: =K33-K34 -> 179160.8
A36: SUPERMERCADO CAMPOS NOVOS | B36: 33.333.713/0001-26 | C36: 0 | D36: 0 | E36: 0 | F36: 0 | G36: 0 | H36: 0 | I36: 0 | J36: JANEIRO
A37: A M MACAE COMERCIO DE ALIMENTOS LTDA | B37: 18.343.960/0001-10 | C37: 0 | D37: 0 | E37: 0 | F37: 0 | G37: 0 | H37: 0 | I37: 0 | J37: JANEIRO
A38: SUPERMERCADO BATISTA | B38: 15.471.879/0001-27 | C38: 0 | D38: 0 | E38: 0 | F38: 0 | G38: 0 | H38: 0 | I38: 0 | J38: JANEIRO
A39: MERCADINHO PAI E FILHA | B39: 18.108.211/0001-08 | C39: 0 | D39: 0 | E39: 0 | F39: 0 | G39: 0 | H39: 0 | I39: 0 | J39: JANEIRO
A40: TOTAL | C40: =SUM(C4:C39) -> 1170638.5 | D40: =SUM(D4:D39) -> 416083.92 | E40: =SUM(E4:E39) -> 0 | F40: =SUM(F4:F39) -> 0 | G40: =SUM(G4:G39) -> 1586722.5 | H40: =SUM(H4:H39) -> 227732.05
...

Sheet fluxo caixa mar 2026
A2: EMPRESAS | B2: CNPJ | C2: VALORES COMPENSADOS | N2: atualizar depois da compensação
C3: DCTF WEB - INSS | D3: PIS COFINS | E3: IRPJ CSLL | F3: DCTWEb IRPJ/CS 3 TRIM /PIS-COF | G3: TOTAL | H3: Honários | I3: % | J3: Comp. | K3: VL NFSE- ENVIO | L3: ENVIO BOLETO | N3: SALDO DE CRÉDITO INSUMOS | O3: SALDO DE CRÉDITO SUBV | P3: CREDITO EXLUSAO ICMS DA BC PIS E CF | Q3: SALDO honorario projeção
A4: MARAVISTA COMERCIO DE ALIMENTOS | B4: 30.140.610/0001-51 | C4: =138832.98+1508.13 -> 140341.11 | D4: 104358.68 | G4: =SUM(C4:E4) -> 244699.79 | H4: =G4*15% -> 36704.969 | I4: 0.15 | J4: FEVEREIRO | K4: =H4 -> 36704.969 | M4: ir mensal | N4: ='fluxo caixa fev 2026'!N4-'fluxo caixa mar 2026'!G4 -> 1329142.5 | O4: ='fluxo caixa dez 2025'!N5 -> 0 | Q4: =N4+O4*I4 -> 1329142.5 | R4: 1.0018664e+22 | S4: 1.0018664e+22
A5: GRANO E FARINA PADARIA E COMERCIO LTDA | B5: 29.056.262/0001-50 | C5: =30872.23+14.61 -> 30886.84 | D5: =5861.9+1272.64 -> 7134.54 | G5: =SUM(C5:E5) -> 38021.38 | H5: =G5*12.5% -> 4752.6725 | I5: 0.125 | J5: FEVEREIRO | K5: =H5 -> 4752.6725 | N5: ='fluxo caixa fev 2026'!N5-'fluxo caixa mar 2026'!G5 -> 391404.32 | O5: ='fluxo caixa dez 2025'!N6 -> 0 | Q5: =N5+O5*I5 -> 391404.32
A6: CGX COMÉRCIO DE ALIMENTOS | B6: 15.580.294/0001-45 | C6: 40274.56 | G6: =SUM(C6:E6) -> 40274.56 | H6: =G6*12.5% -> 5034.32 | I6: 0.125 | J6: FEVEREIRO | K6: =H6 -> 5034.32 | N6: 0 | O6: ='fluxo caixa fev 2026'!O6-'fluxo caixa mar 2026'!G6 -> -278483.61 | Q6: =N6+O6*I6 -> -34810.451
A7: SUPERMERCADO GUIMARAES FILHOS LTDA | B7: 50.547.492/0001-08 | C7: =100631.24 -> 100631.24 | D7: =29104.8+6006.81 -> 35111.61 | G7: =SUM(C7:E7) -> 135742.85 | H7: =G7*12.5% -> 16967.856 | I7: 0.125 | J7: FEVEREIRO | K7: =H7 -> 16967.856 | N7: ='fluxo caixa fev 2026'!N7-'fluxo caixa mar 2026'!G7 -> 363516.98 | O7: 0 | Q7: =N7+O7*I7 -> 363516.98
A8: PEROLA DE NITEROI SUPERMERCADOS LTDA | B8: 16.564.133/0001-20 | C8: =71968.73+17726.56+11+337.55 -> 90043.84 | D8: =30980.09+6725.08 -> 37705.17 | G8: =SUM(C8:E8) -> 127749.01 | H8: =G8*15%-1475.88 -> 17686.471 | I8: 0.15 | J8: FEVEREIRO | K8: =H8 -> 17686.471 | N8: ='fluxo caixa fev 2026'!N8-'fluxo caixa mar 2026'!G8 -> 2135421.1 | O8: =Controle!J13 -> 1047001.6 | Q8: =N8+O8*I8 -> 2292471.3
A9: SUPERMERCADO COURTS LTDA | B9: 00.569.560/0001-61 | C9: =45944.8+11754.39+59.36+316.27 -> 58074.82 | D9: =17451.54+3788.82 -> 21240.36 | G9: =SUM(C9:E9) -> 79315.18 | H9: =G9*20% -> 15863.036 | I9: 0.2 | J9: FEVEREIRO | K9: =H9 -> 15863.036 | O9: ='fluxo caixa fev 2026'!O9-'fluxo caixa mar 2026'!G9 -> -227133.44 | Q9: =N9+O9*I9 -> -45426.688
A10: MERCEARIA 6 ESTRELAS LTDA (Paulo) | B10: 22.546.657/0001-91 | C10: 26136.44 | G10: =SUM(C10:E10) -> 26136.44 | H10: =G10*20% -> 5227.288 | I10: 0.2 | J10: FEVEREIRO | K10: =H10 -> 5227.288 | O10: ='fluxo caixa fev 2026'!O10-'fluxo caixa mar 2026'!G10 -> -291335.91 | Q10: =N10+O10*I10 -> -58267.182
A11: IMPERIUM | B11: 13.159.094/0001-98 | G11: =SUM(C11:E11) -> 0 | H11: =G11*20% -> 0 | J11: FEVEREIRO | K11: =H11 -> 0 | N11: ='fluxo caixa dez 2025'!M12-G11 -> 0 | O11: ='fluxo caixa fev 2026'!O11-'fluxo caixa mar 2026'!G11 -> 0 | Q11: =N11+O11*I11 -> 0
A12: SUPERMERCADO LIBERDADE | B12: 09.633.032/0001-07 | C12: =19308.06+4813.57+78.19 -> 24199.82 | D12: =1664.95+351.17 -> 2016.12 | G12: =SUM(C12:E12) -> 26215.94 | H12: =G12*15% -> 3932.391 | J12: FEVEREIRO | K12: =H12 -> 3932.391 | N12: ='fluxo caixa fev 2026'!N12-'fluxo caixa mar 2026'!G12 -> -116739.51 | O12: ='fluxo caixa dez 2025'!N13 -> 0 | Q12: =N12+O12*I12 -> #VALUE!
A13: SÃO FERNANDO 10 | B13: 11.304.945/0001-13 | C13: 102481.83 | D13: =10464.13+2023.45 -> 12487.58 | G13: =C13+D13+E13 -> 114969.41 | H13: =G13*15% -> 17245.411 | I13: 0.15 | J13: FEVEREIRO | K13: =H13 -> 17245.411 | N13: 0 | O13: 0 | P13: =Controle!K17-E13-12932.11 -> 309926.57 | Q13: =N13+O13*I13 -> 0
A14: SUPREMO | B14: 05.229.674/0001-86 | C14: =33925.27 -> 33925.27 | D14: =7141.46+1550.46 -> 8691.92 | G14: =SUM(C14:E14) -> 42617.19 | H14: =G14*20% -> 8523.438 | I14: 0.2 | J14: FEVEREIRO | K14: =H14 -> 8523.438 | N14: ='fluxo caixa fev 2026'!N14-'fluxo caixa mar 2026'!G14 -> -244142.22 | O14: 0 | Q14: =N14+O14*I14 -> -244142.22
A15: LGH | B15: 26.061.062/0001-05 | C15: =2765.04 -> 2765.04 | G15: =SUM(C15:E15) -> 2765.04 | H15: =G15*20% -> 553.008 | I15: 0.2 | J15: FEVEREIRO | K15: =H15 -> 553.008 | N15: 0 | O15: ='fluxo caixa fev 2026'!O15-'fluxo caixa mar 2026'!G15 -> 59153.02 | Q15: =N15+O15*I15 -> 11830.604
A16: AP MEDEIROS | B16: 31.224.769/0001-17 | C16: 36114.03 | D16: =38662.29+8393.14 -> 47055.43 | G16: =C16+D16+E16 -> 83169.46 | H16: =G16*20% -> 16633.892 | I16: 0.2 | J16: FEVEREIRO | K16: =H16 -> 16633.892 | O16: ='fluxo caixa fev 2026'!O16-'fluxo caixa mar 2026'!G16 -> 1114395.6 | Q16: =N16+O16*I16 -> 222879.13
A17: SUPERMERCADOS FEIRA NOVA LTDA | B17: 36.525.319/0001-88 | H17: =G17*10% -> 0 | I17: 0.1 | J17: FEVEREIRO | K17: =H17 -> 0 | N17: 0 | O17: ='fluxo caixa fev 2026'!O17-'fluxo caixa mar 2026'!G17 -> 0 | P17: ='fluxo caixa jan 2026'!P17-'fluxo caixa mar 2026'!G17 -> 340788.89 | Q17: =N17+O17*I17 -> 0
A18: SUPERMERCADO ECONOMICO JJ LTDA | B18: 22.536.813/0001-33 | C18: =122026.43+428.46 -> 122454.89 | D18: =50508.87+10907.72 -> 61416.59 | G18: =C18+D18+E18 -> 183871.48 | H18: =G18*15% -> 27580.722 | I18: 0.15 | J18: FEVEREIRO | K18: =H18 -> 27580.722 | O18: ='fluxo caixa fev 2026'!O18-'fluxo caixa mar 2026'!G18 -> 760535.36 | P18: 0 | Q18: =N18+O18*I18 -> 114080.3
A19: REZENDE ALIMENTOS NOVA HOLANDA LTDA | B19: 32.254.332/0001-99 | C19: 1913.13 | G19: =C19+D19+E19+F19 -> 1913.13 | H19: =G19*12.5% -> 239.14125 | I19: 0.125 | J19: FEVEREIRO | K19: =H19 -> 239.14125 | N19: 0 | O19: ='fluxo caixa fev 2026'!O19-'fluxo caixa mar 2026'!G19 -> 384352.84 | P19: =Controle!K29 -> 2283.29 | Q19: =N19+O19*I19 -> 48044.105
A20: REZENDE ALIMENTOS JPA LTDA | B20: 50.250.937/0001-93 | C20: =196.16+30.18+61.89+553.27 -> 841.5 | D20: =17276.7+4328.77 -> 21605.47 | G20: =C20+D20+E20+F20 -> 22446.97 | H20: =G20*12.5% -> 2805.8713 | I20: 0.125 | J20: FEVEREIRO | K20: =H20 -> 2805.8713 | N20: ='fluxo caixa fev 2026'!N20-'fluxo caixa mar 2026'!G20 -> 392699 | O20: =Controle!J30-G20+65444.12+12131.07 -> 299759.24 | Q20: =N20+O20*I20 -> 430168.91
A21: MERCADO 24 HORAS DA ROCINHA LTDA | B21: 23.672.895/0001-06 | C21: 574.58 | G21: =C21+D21+E21+F21 -> 574.58 | H21: =G21*12.5% -> 71.8225 | I21: 0.125 | J21: FEVEREIRO | K21: =H21 -> 71.8225 | N21: 0 | O21: ='fluxo caixa fev 2026'!O21-'fluxo caixa mar 2026'!G21 -> 1145906.4 | P21: ='fluxo caixa fev 2026'!P21-'fluxo caixa mar 2026'!G21 -> 66148.85 | Q21: =N21+O21*I21 -> 143238.31
A22: MULTI ALIMENTOS MENDANHA LTDA | B22: 30.807.561/0001-68 | C22: 101.39 | G22: =C22+D22+E22+F22 -> 101.39 | H22: =G22*12.5% -> 12.67375 | I22: 0.125 | J22: FEVEREIRO | K22: =H22 -> 12.67375 | N22: 0 | O22: ='fluxo caixa fev 2026'!O22-'fluxo caixa mar 2026'!G22 -> 254956.29 | P22: 0 | Q22: =N22+O22*I22 -> 31869.536
A23: REZENDE ALIMENTOS CDD LTDA | B23: 28.732.157/0001-20 | C23: 3831.28 | G23: =C23+D23+E23+F23 -> 3831.28 | H23: =G23*12.5% -> 478.91 | I23: 0.125 | J23: FEVEREIRO | K23: =H23 -> 478.91 | N23: 0 | O23: ='fluxo caixa fev 2026'!O21 -> 1146481 | P23: ='fluxo caixa fev 2026'!P23-'fluxo caixa mar 2026'!G23-69.6 -> 225557.85 | Q23: =N23+O23*I23 -> 143310.13
A24: COMERCIAL 2 REZENDE ALIMENTOS LTDA | B24: 17.479.543/0001-36 | C24: 2660.94 | G24: =C24+D24+E24+F24 -> 2660.94 | H24: =G24*12.5% -> 332.6175 | I24: 0.125 | J24: FEVEREIRO | K24: =H24 -> 332.6175 | N24: ='fluxo caixa fev 2026'!N24-'fluxo caixa mar 2026'!G24 -> 30525.26 | O24: 0 | Q24: =N24+O24*I24 -> 30525.26
A25: COMERCIAL DE ALIMENTOS PRIMUS | B25: 05.904.970/0001-35 | C25: 17243.69 | G25: =C25+D25+E25 -> 17243.69 | H25: =G25*20% -> 3448.738 | I25: 0.2 | J25: FEVEREIRO | K25: =H25 -> 3448.738 | N25: ='fluxo caixa fev 2026'!N25-'fluxo caixa mar 2026'!G25 -> 1007523 | O25: =Controle!J35 -> 127712.31 | Q25: =N25+O25*I25 -> 1033065.4
A26: COMERCIAL DE ALIMENTOS MANO | B26: 05.904.978/0001-00 | C26: 2015.54 | G26: =C26+D26+E26 -> 2015.54 | H26: =G26*20% -> 403.108 | I26: 0.2 | J26: FEVEREIRO | K26: =H26 -> 403.108 | N26: ='fluxo caixa fev 2026'!N26-'fluxo caixa mar 2026'!G26 -> 354952.81 | O26: =Controle!J36 -> 206005.26 | Q26: =N26+O26*I26 -> 396153.86
A27: SHOPPING D CARNE BOI DE OURO | B27: 13.373.989/0001-20 | C27: 6771.93 | G27: =C27+D27+E27 -> 6771.93 | H27: =G27*20% -> 1354.386 | I27: 0.2 | J27: FEVEREIRO | K27: =H27 -> 1354.386 | N27: ='fluxo caixa fev 2026'!N27-'fluxo caixa mar 2026'!G27 -> 658816.52 | O27: =Controle!J37 -> 61872.72 | Q27: =N27+O27*I27 -> 671191.06
A28: UNIÃO DA FAMILIA MERCEARIA LTDA | B28: 20.782.168/0001-03 | C28: =7037.95+1705.21+82.06+317.82 -> 9143.04 | D28: =3551.84+743.34 -> 4295.18 | G28: =C28+D28+E28+F28 -> 13438.22 | H28: =G28*20% -> 2687.644 | I28: 0.2 | J28: FEVEREIRO | K28: =H28 -> 2687.644 | N28: ='fluxo caixa fev 2026'!N28-'fluxo caixa mar 2026'!G28 -> 139565.9 | Q28: =N28+O28*I28 -> 139565.9
A29: MERCADO UNIÃO DE NOVA BRASILIA LTDA | B29: 30.285.758/0001-84 | C29: 7306.73 | D29: =2944.38+639.24 -> 3583.62 | G29: =C29+D29+E29+F29 -> 10890.35 | H29: =G29*20% -> 2178.07 | I29: 0.2 | J29: FEVEREIRO | K29: =H29 -> 2178.07 | N29: ='fluxo caixa fev 2026'!N29-'fluxo caixa mar 2026'!G29 -> 82266.04 | Q29: =N29+O29*I29 -> 82266.04 | R29: 4.1937811e+20 | S29: 2.4894114e+22 | T29: 4.1524508e+22
A30: MULTIMIX | B30: 03.307.464/0001-33 | C30: =69999.75 -> 69999.75 | G30: =C30+D30+E30+F30 -> 69999.75 | H30: =G30*20% -> 13999.95 | I30: 0.2 | J30: FEVEREIRO | K30: =H30 -> 13999.95
A31: EMPORIO PETROPOLIS | B31: 15.202.462/0001-69 | C31: 157151.32 | D31: =13072.67+60971.78 -> 74044.45 | G31: =C31+D31+E31+F31 -> 231195.77 | H31: =G31*20% -> 46239.154 | I31: 0.2 | J31: FEVEREIRO | K31: =H31 -> 46239.154 | Q31: =N31+O31*I31 -> 0
A32: PADARIA JANDRES | B32: 10.440.200/0001-19 | C32: =14233.58+1429.71 -> 15663.29 | D32: =2041.04+9401.47 -> 11442.51 | G32: =C32+D32+E32+F32 -> 27105.8 | H32: =G32*20% -> 5421.16 | I32: 0.2 | J32: FEVEREIRO | K32: =H32 -> 5421.16 | N32: =Controle!I43-'fluxo caixa mar 2026'!G32 -> 173144.8 | Q32: =N32+O32*I32 -> 173144.8
A33: REUNIDOS | B33: 32.352.751/0001-63 | C33: =171499.06+522940.64+139226.25+22965.13+6898.77 -> 863529.85 | D33: =214670.65+46295.25 -> 260965.9 | G33: =C33+D33+E33+F33 -> 1124495.8 | H33: =G33*20% -> 224899.15 | I33: 0.1 | J33: FEVEREIRO | K33: =H33 -> 224899.15 | N33: =Controle!I44-G33 -> 3139844.8 | O33: =Controle!J44 -> 2840879.7 | P33: =Controle!K44 -> 119503.56
A34: PRINCESA | B34: 27.833.615/0001-55 | F34: 1894338.3 | G34: =C34+D34+E34+F34 -> 1894338.3 | H34: =G34*10%/4 -> 47358.457 | I34: 0.1 | J34: FEVEREIRO | K34: =H34 -> 47358.457
A35: SOLIDCON BARRA INFORMATICA LTDA | B35: 04.782.837/0001-90 | G35: =C35+D35+E35+F35 -> 0 | H35: =G35*10%/4 -> 0 | I35: 0 | J35: FEVEREIRO
A36: SUPERMERCADO CAMPOS NOVOS | B36: 33.333.713/0001-26 | G36: =C36+D36+E36+F36 -> 0 | H36: =G36*10%/4 -> 0 | I36: 0 | J36: FEVEREIRO
A37: A M MACAE COMERCIO DE ALIMENTOS LTDA | B37: 18.343.960/0001-10 | G37: =C37+D37+E37+F37 -> 0 | H37: =G37*10%/4 -> 0 | I37: 0 | J37: FEVEREIRO | K37: =SUM(K4:K36) -> 528636.33 | O37: =SUM(O4:O27) -> 5811178.8 | P37: =SUM(P4:P27) -> 944705.45 | Q37: =SUM(Q4:Q32) -> #VALUE!
A38: SUPERMERCADO BATISTA | B38: 15.471.879/0001-27 | G38: =C38+D38+E38+F38 -> 0 | H38: =G38*10%/4 -> 0 | I38: 0 | J38: FEVEREIRO | K38: =K37*20% -> 105727.27
A39: MERCADINHO PAI E FILHA | B39: 18.108.211/0001-08 | G39: =C39+D39+E39+F39 -> 0 | H39: =G39*10%/4 -> 0 | I39: 0 | J39: FEVEREIRO | K39: =K37-K38 -> 422909.06
A40: TOTAL | C40: =SUM(C4:C39) -> 1967077.7 | D40: =SUM(D4:D39) -> 713155.13 | E40: =SUM(E4:E39) -> 0 | F40: =SUM(F4:F39) -> 1894338.3 | G40: =SUM(G4:G39) -> 4574571.1 | H40: =SUM(H4:H39) -> 528636.33 | J40: =SUM(J4:J39) -> 0
E51: ,

Sheet fluxo caixa abr 2026 
A1: MARÇO - 2026 | H1: Honários | I1: % | J1: Comp. | K1: VL NFSE- ENVIO | L1: ENVIO BOLETO | N1: SALDO CRÉDITOS E TESES | S1: 3
A2: EMPRESAS | B2: CNPJ | C2: VALORES COMPENSADOS
C3: DCTF WEB - INSS | D3: PIS COFINS | E3: IRPJ CSLL | F3: TOTAL | G3: MAPA | N3: SALDO DE CRÉDITO INSUMOS | O3: SALDO DE CRÉDITO SUBV | P3: PREVIDENCIARIO | Q3: CREDITO EXLUSAO ICMS st DA BC PIS E CF | R3: SALDO honorario projeção
A4: MARAVISTA COMERCIO DE ALIMENTOS | B4: 30.140.610/0001-51 | C4: 142323.01 | D4: 78314.52 | E4: 981876.55 | F4: =SUM(C4:E4) -> 1202514.1 | H4: =F4*15% -> 180377.11 | I4: 0.15 | J4: MARÇO | K4: =H4 -> 180377.11 | N4: ='fluxo caixa mar 2026'!N4-'fluxo caixa abr 2026 '!F4 -> 126628.46 | O4: ='fluxo caixa dez 2025'!N5 -> 0 | R4: =N4+O4*I4 -> 126628.46
A5: GRANO E FARINA PADARIA E COMERCIO LTDA | B5: 29.056.262/0001-50 | C5: 29725.33 | D5: =6476.35+1406.05 -> 7882.4 | E5: =3246.13+1947.68 -> 5193.81 | F5: =SUM(C5:E5) -> 42801.54 | G5: OK | H5: =F5*12.5% -> 5350.1925 | I5: 0.125 | J5: MARÇO | K5: =H5 -> 5350.1925 | N5: ='fluxo caixa mar 2026'!N5-'fluxo caixa abr 2026 '!F5 -> 348602.78 | O5: ='fluxo caixa dez 2025'!N6 -> 0 | R5: =N5+O5*I5 -> 348602.78
A6: CGX COMÉRCIO DE ALIMENTOS | B6: 15.580.294/0001-45 | C6: 40430.77 | D6: 0 | E6: =55368.72+22092.74 -> 77461.46 | F6: =SUM(C6:E6) -> 117892.23 | G6: ok | H6: =F6*12.5% -> 14736.529 | I6: 0.125 | J6: MARÇO | K6: =H6 -> 14736.529 | O6: ='fluxo caixa mar 2026'!O6-'fluxo caixa abr 2026 '!F6 -> -396375.84 | R6: =N6+O6*I6 -> -49546.98
A7: SUPERMERCADO GUIMARAES FILHOS LTDA | B7: 50.547.492/0001-08 | C7: 106181.1 | D7: 28847.29 | E7: =24262.64+10894.55 -> 35157.19 | F7: =SUM(C7:E7) -> 170185.58 | H7: =F7*12.5% -> 21273.198 | I7: 0.125 | J7: MARÇO | K7: =H7 -> 21273.198 | N7: ='fluxo caixa mar 2026'!N7-'fluxo caixa abr 2026 '!F7 -> 193331.4 | O7: 0 | R7: =N7+O7*I7 -> 193331.4
A8: PEROLA DE NITEROI SUPERMERCADOS LTDA | B8: 16.564.133/0001-20 | C8: 90697.81 | D8: 44071.69 | F8: =SUM(C8:E8) -> 134769.5 | H8: =F8*15% -> 20215.425 | I8: 0.15 | J8: MARÇO | K8: =H8 -> 20215.425 | N8: ='fluxo caixa mar 2026'!N8-'fluxo caixa abr 2026 '!F8 -> 2000651.6 | O8: =Controle!J13 -> 1047001.6 | R8: =N8+O8*I8 -> 2157701.8
A9: SUPERMERCADO COURTS LTDA | B9: 00.569.560/0001-61 | C9: =55.83+299.85+46908.78+12005.78 -> 59270.24 | D9: 7301.88 | E9: 23144.54 | F9: =SUM(C9:E9) -> 89716.66 | G9: OK | H9: =F9*20% -> 17943.332 | I9: 0.2 | J9: MARÇO | K9: =H9 -> 17943.332 | N9: =Controle!I15-'fluxo caixa abr 2026 '!F9+'fluxo caixa mar 2026'!O9 -> 243849.9 | O9: 0 | R9: =N9+O9*I9 -> 243849.9
A10: MERCEARIA 6 ESTRELAS LTDA (Paulo) | B10: 22.546.657/0001-91 | C10: =193.77+5357.47+20441.5 -> 25992.74 | D10: 0 | E10: =33374.65+14174.88 -> 47549.53 | F10: =SUM(C10:E10) -> 73542.27 | G10: OK | H10: =F10*20% -> 14708.454 | I10: 0.2 | J10: MARÇO | K10: =H10 -> 14708.454 | O10: ='fluxo caixa mar 2026'!O10-'fluxo caixa abr 2026 '!F10 -> -364878.18 | R10: =N10+O10*I10 -> -72975.636
A11: IMPERIUM GENEROS ALIMENTICIOS LTDA | B11: 13.159.094/0001-98 | C11: 0 | D11: 0 | E11: 0 | I11: 0 | J11: MARÇO
A12: SUPERMERCADO LIBERDADE | B12: 09.633.032/0001-07 | C12: 24604.93 | D12: =901.48+185.43 -> 1086.91 | E12: =28321.34+12355.68 -> 40677.02 | F12: =SUM(C12:E12) -> 66368.86 | G12: OK | H12: =F12*15% -> 9955.329 | I12: 0.15 | J12: MARÇO | K12: =H12 -> 9955.329 | N12: 0 | O12: ='fluxo caixa dez 2025'!N13-43102.88 -> -43102.88 | R12: =N12+O12*I12 -> -6465.432
A13: SÃO FERNANDO 10 | B13: 11.304.945/0001-13 | C13: 107640.38 | D13: 39009.66 | E13: 231810.01 | F13: =SUM(C13:E13) -> 378460.05 | G13: OK (SALDO) | H13: =F13*15% -> 56769.008 | I13: 0.15 | J13: MARÇO | K13: =H13 -> 56769.008 | N13: =390560-F13 -> 12099.95 | O13: 0 | Q13: =Controle!K17-E13-12932.11 -> 78116.561 | R13: =N13+O13*I13 -> 12099.95
A14: SUPREMO | B14: 05.229.674/0001-86 | C14: =26628.15+6490.2+43.53+207.33 -> 33369.21 | D14: =5159.92+1120.24 -> 6280.16 | E14: =99454.88+37963.76 -> 137418.64 | F14: =SUM(C14:E14) -> 177068.01 | H14: =F14*20% -> 35413.602 | I14: 0.2 | J14: MARÇO | K14: =H14 -> 35413.602 | N14: ='fluxo caixa mar 2026'!N14-'fluxo caixa abr 2026 '!F14 -> -421210.23 | O14: 0 | Q14: =Controle!K16-'fluxo caixa abr 2026 '!F14+13174.49 -> 86706.48 | R14: =N14+O14*I14 -> -421210.23
A15: LGH | B15: 26.061.062/0001-05 | C15: 2798.61 | E15: =38187.21+15907.4 -> 54094.61 | F15: =SUM(C15:E15) -> 56893.22 | G15: OK (SALDO) | H15: =F15*20% -> 11378.644 | I15: 0.2 | J15: MARÇO | K15: =H15 -> 11378.644 | N15: 0 | O15: ='fluxo caixa mar 2026'!O15-'fluxo caixa abr 2026 '!F15 -> 2259.8 | R15: =N15+O15*I15 -> 451.96
A16: AP MEDEIROS | B16: 31.224.769/0001-17 | C16: 37572.3 | D16: =20896.98+4535.81 -> 25432.79 | E16: =158612.6+59260.53 -> 217873.13 | F16: =SUM(C16:E16) -> 280878.22 | G16: OK | H16: =F16*20% -> 56175.644 | I16: 0.2 | J16: MARÇO | K16: =H16 -> 56175.644 | O16: ='fluxo caixa mar 2026'!O16-'fluxo caixa abr 2026 '!F16 -> 833517.41 | R16: =N16+O16*I16 -> 166703.48
A17: SUPERMERCADOS FEIRA NOVA LTDA | B17: 36.525.319/0001-88 | C17: 0 | D17: 0 | E17: 0 | H17: 0 | I17: 0.1 | J17: MARÇO | K17: =H17 -> 0 | N17: 0 | O17: ='fluxo caixa fev 2026'!O17-'fluxo caixa mar 2026'!G17 -> 0 | P17: ='fluxo caixa jan 2026'!P17-'fluxo caixa mar 2026'!G17 -> 340788.89 | Q17: =N17+O17*I17 -> 0
A18: SUPERMERCADO ECONOMICO JJ LTDA | B18: 22.536.813/0001-33 | C18: 125416.7 | D18: 19386.25 | E18: 83603.41 | F18: =SUM(C18:E18) -> 228406.36 | G18: OK | H18: =F18*15% -> 34260.954 | I18: 0.15 | J18: MARÇO | K18: =H18 -> 34260.954 | O18: ='fluxo caixa mar 2026'!O17-'fluxo caixa abr 2026 '!F18 -> -228406.36 | Q18: 0 | R18: =N18+O18*I18 -> -34260.954
A19: REZENDE ALIMENTOS NOVA HOLANDA LTDA | B19: 32.254.332/0001-99 | C19: 2017.35 | D19: 0 | E19: 0 | F19: =SUM(C19:E19) -> 2017.35 | H19: =F19*12.5% -> 252.16875 | I19: 0.125 | J19: MARÇO | K19: =H19 -> 252.16875 | N19: 0 | O19: ='fluxo caixa mar 2026'!O19-'fluxo caixa abr 2026 '!F19 -> 382335.49 | Q19: =Controle!K29 -> 2283.29 | R19: =N19+O19*I19 -> 47791.936
